Workbook

Sheet Summary Dashboard
A1: Co-existence Summary Dashboard | N1: Selected Cost Component | O1: Value | Q1: Utilisation View | R1: Rate | T1: Branch | U1: Co-existence Cost (£)
N2: Annual Leave | O2: =IF($B$3="All",'Baseline Data'!C13,INDEX('Baseline Data'!$C$4:$C$12,MATCH($B$3,'Baseline Data'!$A$4:$A$12,0))) -> 17968.027 | Q2: Selected Branch | R2: =IF($B$3="All",'Baseline Data'!B13,INDEX('Baseline Data'!$B$4:$B$12,MATCH($B$3,'Baseline Data'!$A$4:$A$12,0))) -> 0.51179762 | T2: Birmingham | U2: 78320.831
A3: Branch View | B3: Cambridge | D3: Select a branch to update the KPIs and branch-specific charts. National internal recharge is controlled to £0. | N3: Other Leave | O3: =IF($B$3="All",'Baseline Data'!D13,INDEX('Baseline Data'!$D$4:$D$12,MATCH($B$3,'Baseline Data'!$A$4:$A$12,0))) -> 2487.086 | Q3: National | R3: 0.80335832 | T3: Bristol | U3: 12998.51
N4: Operational Under-utilisation | O4: =IF($B$3="All",'Baseline Data'!E13,INDEX('Baseline Data'!$E$4:$E$12,MATCH($B$3,'Baseline Data'!$A$4:$A$12,0))) -> 119583.82 | T4: Cambridge | U4: 134491.09
A5: Contract Utilisation | C5: Annual Leave Cost | E5: Other Leave Cost | G5: Operational Under-utilisation | I5: Avoidable Agency Cost | K5: Co-existence Cost | N5: Avoidable Agency | O5: =IF($B$3="All",'Baseline Data'!G13,INDEX('Baseline Data'!$G$4:$G$12,MATCH($B$3,'Baseline Data'!$A$4:$A$12,0))) -> 12420.184 | T5: Croydon | U5: 56011.18
A6: =IF($B$3="All",'Baseline Data'!B13,INDEX('Baseline Data'!$B$4:$B$12,MATCH($B$3,'Baseline Data'!$A$4:$A$12,0))) -> 0.51179762 | C6: =IF($B$3="All",'Baseline Data'!C13,INDEX('Baseline Data'!$C$4:$C$12,MATCH($B$3,'Baseline Data'!$A$4:$A$12,0))) -> 17968.027 | E6: =IF($B$3="All",'Baseline Data'!D13,INDEX('Baseline Data'!$D$4:$D$12,MATCH($B$3,'Baseline Data'!$A$4:$A$12,0))) -> 2487.086 | G6: =IF($B$3="All",'Baseline Data'!E13,INDEX('Baseline Data'!$E$4:$E$12,MATCH($B$3,'Baseline Data'!$A$4:$A$12,0))) -> 119583.82 | I6: =IF($B$3="All",'Baseline Data'!G13,INDEX('Baseline Data'!$G$4:$G$12,MATCH($B$3,'Baseline Data'!$A$4:$A$12,0))) -> 12420.184 | K6: =IF($B$3="All",'Baseline Data'!I13,INDEX('Baseline Data'!$I$4:$I$12,MATCH($B$3,'Baseline Data'!$A$4:$A$12,0))) -> 134491.09 | N6: Structural Agency | O6: =IF($B$3="All",'Baseline Data'!H13,INDEX('Baseline Data'!$H$4:$H$12,MATCH($B$3,'Baseline Data'!$A$4:$A$12,0))) -> 3240.4962 | T6: Glasgow | U6: 41954.727
N7: Internal Recharge | O7: =IF($B$3="All",'Baseline Data'!J13,INDEX('Baseline Data'!$J$4:$J$12,MATCH($B$3,'Baseline Data'!$A$4:$A$12,0))) -> -3642 | T7: Leeds | U7: 49451.037
T8: Manchester | U8: 39935.45
T9: Oxford | U9: 33470.679
A10: Branch | B10: Utilisation | C10: Annual Leave (£) | D10: Other Leave (£) | E10: Under-utilisation (£) | F10: Permanent Inefficiency (£) | G10: Avoidable Agency (£) | H10: Structural Agency (£) | I10: Co-existence (£) | J10: Internal Recharge (£) | T10: Thurrock | U10: 263506.07
A11: Birmingham | B11: 0.81685426 | C11: 20835.907 | D11: 731.8147 | E11: 49219.675 | F11: 49951.489 | G11: 28369.342 | H11: 66147.128 | I11: 78320.831 | J11: 7598.1
A12: Bristol | B12: 0.81599115 | C12: 2779.7198 | D12: 0 | E12: 6718.735 | F12: 6718.735 | G12: 6279.775 | H12: 35179.335 | I12: 12998.51 | J12: -3108
A13: Cambridge | B13: 0.51179762 | C13: 17968.027 | D13: 2487.086 | E13: 119583.82 | F13: 122070.91 | G13: 12420.184 | H13: 3240.4962 | I13: 134491.09 | J13: -3642
A14: Croydon | B14: 0.84456027 | C14: 24766.222 | D14: 892.95262 | E14: 37303.472 | F14: 38196.424 | G14: 17814.755 | H14: 58303.995 | I14: 56011.18 | J14: -6552.5
A15: Glasgow | B15: 0.70348743 | C15: 5380.0165 | D15: 839.09038 | E15: 23379.1 | F15: 24218.191 | G15: 17736.537 | H15: 60612.163 | I15: 41954.727 | J15: 5504
A16: Leeds | B16: 0.76501684 | C16: 8904.1362 | D16: 52.283183 | E16: 27638.672 | F16: 27690.955 | G16: 21760.082 | H16: 116832.75 | I16: 49451.037 | J16: 22924.34
A17: Manchester | B17: 0.77132209 | C17: 19136.894 | D17: 4889.1534 | E17: 28516.132 | F17: 33405.285 | G17: 6530.1655 | H17: 35089.104 | I17: 39935.45 | J17: -40189.94
A18: Oxford | B18: 0.61594625 | C18: 9009.9949 | D18: 2250.0007 | E18: 27002.785 | F18: 29252.786 | G18: 4217.8932 | H18: 5691.5468 | I18: 33470.679 | J18: 9799
A19: Thurrock | B19: 0.88300312 | C19: 145306.63 | D19: 36170.749 | E19: 136284.32 | F19: 172455.07 | G19: 91051.001 | H19: 175500.06 | I19: 263506.07 | J19: 7667
A21: Control | B21: Value | C21: Status
A22: National internal recharge | B22: ='Baseline Data'!J13 -> 0 | C22: =IF(ABS(B22)<0.01,"PASS — £0 nationally","REVIEW") -> PASS — £0 nationally
A23: Current-period selected utilisation | B23: =IF($B$3="All",'Current Period'!B13,INDEX('Current Period'!$B$4:$B$12,MATCH($B$3,'Current Period'!$A$4:$A$12,0))) -> 0.56958878 | C23: Costs remain provisional

Sheet Baseline Data
A1: Costed Baseline to 28 June 2026
A3: Branch | B3: Contract Utilisation | C3: Annual Leave Cost (£) | D3: Other Leave Cost (£) | E3: Operational Under-utilisation (£) | F3: Permanent Inefficiency (£) | G3: Avoidable Agency (£) | H3: Structural Agency (£) | I3: Co-existence (£) | J3: Internal Recharge In / (Out) (£)
A4: Birmingham | B4: 0.81685426 | C4: 20835.907 | D4: 731.8147 | E4: 49219.675 | F4: 49951.489 | G4: 28369.342 | H4: 66147.128 | I4: 78320.831 | J4: 7598.1
A5: Bristol | B5: 0.81599115 | C5: 2779.7198 | D5: 0 | E5: 6718.735 | F5: 6718.735 | G5: 6279.775 | H5: 35179.335 | I5: 12998.51 | J5: -3108
A6: Cambridge | B6: 0.51179762 | C6: 17968.027 | D6: 2487.086 | E6: 119583.82 | F6: 122070.91 | G6: 12420.184 | H6: 3240.4962 | I6: 134491.09 | J6: -3642
A7: Croydon | B7: 0.84456027 | C7: 24766.222 | D7: 892.95262 | E7: 37303.472 | F7: 38196.424 | G7: 17814.755 | H7: 58303.995 | I7: 56011.18 | J7: -6552.5
A8: Glasgow | B8: 0.70348743 | C8: 5380.0165 | D8: 839.09038 | E8: 23379.1 | F8: 24218.191 | G8: 17736.537 | H8: 60612.163 | I8: 41954.727 | J8: 5504
A9: Leeds | B9: 0.76501684 | C9: 8904.1362 | D9: 52.283183 | E9: 27638.672 | F9: 27690.955 | G9: 21760.082 | H9: 116832.75 | I9: 49451.037 | J9: 22924.34
A10: Manchester | B10: 0.77132209 | C10: 19136.894 | D10: 4889.1534 | E10: 28516.132 | F10: 33405.285 | G10: 6530.1655 | H10: 35089.104 | I10: 39935.45 | J10: -40189.94
A11: Oxford | B11: 0.61594625 | C11: 9009.9949 | D11: 2250.0007 | E11: 27002.785 | F11: 29252.786 | G11: 4217.8932 | H11: 5691.5468 | I11: 33470.679 | J11: 9799
A12: Thurrock | B12: 0.88300312 | C12: 145306.63 | D12: 36170.749 | E12: 136284.32 | F12: 172455.07 | G12: 91051.001 | H12: 175500.06 | I12: 263506.07 | J12: 7667
A13: National | B13: 0.80335832 | C13: 254087.55 | D13: 48313.13 | E13: 455646.72 | F13: 503959.85 | G13: 206179.73 | H13: 556596.58 | I13: 710139.58 | J13: 0

Sheet Current Period
A1: Current Period — 29 June to 16 July 2026
A3: Branch | B3: Contract Utilisation | C3: Uncosted Agency Days
A4: Birmingham | B4: 0.81940299 | C4: 79
A5: Bristol | B5: 0.84316975 | C5: 41
A6: Cambridge | B6: 0.56958878 | C6: 13
A7: Croydon | B7: 0.69579437 | C7: 113
A8: Glasgow | B8: 0.77741284 | C8: 50
A9: Leeds | B9: 0.77327935 | C9: 51
A10: Manchester | B10: 0.81613757 | C10: 4
A11: Oxford | B11: 0.37333333 | C11: 10
A12: Thurrock | B12: 0.82456708 | C12: 159
A13: National | B13: 0.76320006 | C13: 520

Sheet Activity Daily Summary
A1: Daily Individual Activity Source — 1 to 16 July 2026
A3: Key | B3: Date | C3: Name | D3: Employment Status | E3: Activity Branch | F3: Reporting Role | G3: Jobs | H3: Customers | I3: Actual Hours | J3: Activity Code | K3: Activity Detail
A4: A Apanisile|2026-07-01 | B4: 46204 | C4: A Apanisile | D4: Permanent | E4: Thurrock | F4: Operative Porter | G4: 402264 | H4: AlixPartners LLP | I4: 7.5 | J4: Worked | K4: Worked: 1 record(s) | Branch: Thurrock | Role: Operative Porter | Jobs: 402264 | Customers: AlixPartners LLP | Hours: 7.5
A5: A Apanisile|2026-07-02 | B5: 46205 | C5: A Apanisile | D5: Permanent | E5: Thurrock | F5: Operative Porter | G5: 401175 | H5: Hogan Lovells LLP | I5: 5.5 | J5: Worked | K5: Worked: 1 record(s) | Branch: Thurrock | Role: Operative Porter | Jobs: 401175 | Customers: Hogan Lovells LLP | Hours: 5.5
A6: A Apanisile|2026-07-03 | B6: 46206 | C6: A Apanisile | D6: Permanent | E6: Thurrock | F6: Operative Porter | G6: 401175 | H6: Hogan Lovells LLP | I6: 17 | J6: Worked | K6: Worked: 1 record(s) | Branch: Thurrock | Role: Operative Porter | Jobs: 401175 | Customers: Hogan Lovells LLP | Hours: 17.0
A7: A Apanisile|2026-07-06 | B7: 46209 | C7: A Apanisile | D7: Permanent | E7: Thurrock | F7: Operative Porter | G7: 401175 | H7: Hogan Lovells LLP | I7: 11.5 | J7: Worked | K7: Worked: 1 record(s) | Branch: Thurrock | Role: Operative Porter | Jobs: 401175 | Customers: Hogan Lovells LLP | Hours: 11.5
A8: A Apanisile|2026-07-07 | B8: 46210 | C8: A Apanisile | D8: Permanent | E8: Thurrock | F8: Operative Skilled | G8: 403219 | H8: Jurado/Slendy | I8: 8.5 | J8: Worked | K8: Worked: 1 record(s) | Branch: Thurrock | Role: Operative Skilled | Jobs: 403219 | Customers: Jurado/Slendy | Hours: 8.5
A9: A Apanisile|2026-07-08 | B9: 46211 | C9: A Apanisile | D9: Permanent | E9: Thurrock | F9: Operative Skilled | G9: 403219 | H9: Jurado/Slendy | I9: 8 | J9: Worked | K9: Worked: 1 record(s) | Branch: Thurrock | Role: Operative Skilled | Jobs: 403219 | Customers: Jurado/Slendy | Hours: 8.0
A10: A Apanisile|2026-07-09 | B10: 46212 | C10: A Apanisile | D10: Permanent | E10: Thurrock | F10: Operative Skilled | G10: 398126 | H10: Saunders/Tracey | I10: 8.5 | J10: Worked | K10: Worked: 1 record(s) | Branch: Thurrock | Role: Operative Skilled | Jobs: 398126 | Customers: Saunders/Tracey | Hours: 8.5
A11: A Apanisile|2026-07-10 | B11: 46213 | C11: A Apanisile | D11: Permanent | E11: Thurrock | F11: Operative Porter | G11: 403150, 403315 | H11: Bank of America Merrill Lynch; Knotel UK Ltd | I11: 15 | J11: Worked — 2 records | K11: Worked: 2 record(s) | Branch: Thurrock | Role: Operative Porter | Jobs: 403150, 403315 | Customers: Bank of America Merrill Lynch; Knotel UK Ltd | Hours: 15.0
A12: A Apanisile|2026-07-11 | B12: 46214 | C12: A Apanisile | D12: Permanent | E12: Thurrock | F12: Operative Porter | G12: 403315 | H12: Bank of America Merrill Lynch | I12: 8.5 | J12: Worked | K12: Worked: 1 record(s) | Branch: Thurrock | Role: Operative Porter | Jobs: 403315 | Customers: Bank of America Merrill Lynch | Hours: 8.5
A13: A Apanisile|2026-07-13 | B13: 46216 | C13: A Apanisile | D13: Permanent | E13: Thurrock | F13: Operative Porter | G13: 398446 | H13: Royal Entomological society | I13: 8.5 | J13: Worked | K13: Worked: 1 record(s) | Branch: Thurrock | Role: Operative Porter | Jobs: 398446 | Customers: Royal Entomological society | Hours: 8.5
A14: A Apanisile|2026-07-14 | B14: 46217 | C14: A Apanisile | D14: Permanent | E14: Thurrock | F14: Operative Porter | G14: 398446 | H14: Royal Entomological society | I14: 11 | J14: Worked | K14: Worked: 1 record(s) | Branch: Thurrock | Role: Operative Porter | Jobs: 398446 | Customers: Royal Entomological society | Hours: 11.0
A15: A Apanisile|2026-07-15 | B15: 46218 | C15: A Apanisile | D15: Permanent | E15: Thurrock | F15: Operative Porter | G15: 398446 | H15: Royal Entomological society | I15: 8 | J15: Worked | K15: Worked: 1 record(s) | Branch: Thurrock | Role: Operative Porter | Jobs: 398446 | Customers: Royal Entomological society | Hours: 8.0
... A231: D Wawrzewski|2026-07-01 | B231: 46204 | C231: D Wawrzewski | D231: Permanent | E231: Thurrock | F231: Operative Porter | G231: 400288 | H231: Apple Europe Limited | I231: 11.5 | J231: Worked | K231: Worked: 1 record(s) | Branch: Thurrock | Role: Operative Porter | Jobs: 400288 | Customers: Apple Europe Limited | Hours: 11.5
A232: D Wawrzewski|2026-07-10 | B232: 46213 | C232: D Wawrzewski | I232: 0 | J232: Annual leave | K232: Leave: Annual Leave (Days)
A233: D Wawrzewski|2026-07-13 | B233: 46216 | C233: D Wawrzewski | D233: Permanent | E233: Thurrock | F233: Operative Porter | G233: 400288 | H233: Apple Europe Limited | I233: 11.5 | J233: Worked | K233: Worked: 1 record(s) | Branch: Thurrock | Role: Operative Porter | Jobs: 400288 | Customers: Apple Europe Limited | Hours: 11.5
A234: D Wawrzewski|2026-07-14 | B234: 46217 | C234: D Wawrzewski | D234: Permanent | E234: Thurrock | F234: Operative Porter | G234: 400288 | H234: Apple Europe Limited | I234: 11.5 | J234: Worked | K234: Worked: 1 record(s) | Branch: Thurrock | Role: Operative Porter | Jobs: 400288 | Customers: Apple Europe Limited | Hours: 11.5
A235: D Wawrzewski|2026-07-15 | B235: 46218 | C235: D Wawrzewski | D235: Permanent | E235: Thurrock | F235: Operative Porter | G235: 400288 | H235: Apple Europe Limited | I235: 11.5 | J235: Worked | K235: Worked: 1 record(s) | Branch: Thurrock | Role: Operative Porter | Jobs: 400288 | Customers: Apple Europe Limited | Hours: 11.5
A236: Dam Robinson|2026-07-01 | B236: 46204 | C236: Dam Robinson | D236: Permanent | E236: Thurrock | F236: Operative Porter | G236: 403036 | H236: Russell Reynolds Assoc | I236: 8.5 | J236: Worked | K236: Worked: 1 record(s) | Branch: Thurrock | Role: Operative Porter | Jobs: 403036 | Customers: Russell Reynolds Assoc | Hours: 8.5
A237: Dam Robinson|2026-07-02 | B237: 46205 | C237: Dam Robinson | D237: Permanent | E237: Thurrock | F237: Operative Porter | G237: 402575 | H237: Latham & Watkins | I237: 8.5 | J237: Worked | K237: Worked: 1 record(s) | Branch: Thurrock | Role: Operative Porter | Jobs: 402575 | Customers: Latham & Watkins | Hours: 8.5
A238: Dam Robinson|2026-07-03 | B238: 46206 | C238: Dam Robinson | D238: Permanent | E238: Thurrock | F238: Operative Porter | G238: 402575 | H238: Latham & Watkins | I238: 8.5 | J238: Worked | K238: Worked: 1 record(s) | Branch: Thurrock | Role: Operative Porter | Jobs: 402575 | Customers: Latham & Watkins | Hours: 8.5
A239: Dam Robinson|2026-07-06 | B239: 46209 | C239: Dam Robinson | D239: Permanent | E239: Thurrock | F239: Operative Porter | G239: 402575 | H239: Latham & Watkins | I239: 8.5 | J239: Worked | K239: Worked: 1 record(s) | Branch: Thurrock | Role: Operative Porter | Jobs: 402575 | Customers: Latham & Watkins | Hours: 8.5
A240: Dam Robinson|2026-07-07 | B240: 46210 | C240: Dam Robinson | D240: Permanent | E240: Thurrock | F240: Operative Porter | G240: 402575 | H240: Latham & Watkins | I240: 8.5 | J240: Worked | K240: Worked: 1 record(s) | Branch: Thurrock | Role: Operative Porter | Jobs: 402575 | Customers: Latham & Watkins | Hours: 8.5
A241: Dam Robinson|2026-07-08 | B241: 46211 | C241: Dam Robinson | D241: Permanent | E241: Thurrock | F241: Operative Porter | G241: 402575 | H241: Latham & Watkins | I241: 8.5 | J241: Worked | K241: Worked: 1 record(s) | Branch: Thurrock | Role: Operative Porter | Jobs: 402575 | Customers: Latham & Watkins | Hours: 8.5
A242: Dam Robinson|2026-07-09 | B242: 46212 | C242: Dam Robinson | D242: Permanent | E242: Thurrock | F242: Operative Porter | G242: 402575 | H242: Latham & Watkins | I242: 8.5 | J242: Worked | K242: Worked: 1 record(s) | Branch: Thurrock | Role: Operative Porter | Jobs: 402575 | Customers: Latham & Watkins | Hours: 8.5
A243: Dam Robinson|2026-07-10 | B243: 46213 | C243: Dam Robinson | D243: Permanent | E243: Thurrock | F243: Operative Porter | G243: 402575 | H243: Latham & Watkins | I243: 8.5 | J243: Worked | K243: Worked: 1 record(s) | Branch: Thurrock | Role: Operative Porter | Jobs: 402575 | Customers: Latham & Watkins | Hours: 8.5
A244: Dam Robinson|2026-07-13 | B244: 46216 | C244: Dam Robinson | D244: Permanent | E244: Thurrock | F244: Operative Porter | G244: 398446 | H244: Royal Entomological society | I244: 8.5 | J244: Worked | K244: Worked: 1 record(s) | Branch: Thurrock | Role: Operative Porter | Jobs: 398446 | Customers: Royal Entomological society | Hours: 8.5
... A371: Geoff Malpas|2026-07-08 | B371: 46211 | C371: Geoff Malpas | D371: Permanent | E371: Bristol | F371: Operative Porter | G371: 375286A | H371: BCC - 167 Rodbourne Road | I371: 8 | J371: Worked | K371: Worked: 1 record(s) | Branch: Bristol | Role: Operative Porter | Jobs: 375286A | Customers: BCC - 167 Rodbourne Road | Hours: 8.0
A372: Geoff Malpas|2026-07-09 | B372: 46212 | C372: Geoff Malpas | I372: 0 | J372: Annual leave | K372: Leave: Annual Leave (Hours)
A373: Geoff Malpas|2026-07-10 | B373: 46213 | C373: Geoff Malpas | I373: 0 | J373: Annual leave | K373: Leave: Annual Leave (Hours)
A374: Geoff Malpas|2026-07-13 | B374: 46216 | C374: Geoff Malpas | D374: Permanent | E374: Bristol | F374: Operative Porter | G374: 402750 | H374: Barbican/ Cardiff Uni | I374: 11 | J374: Worked | K374: Worked: 1 record(s) | Branch: Bristol | Role: Operative Porter | Jobs: 402750 | Customers: Barbican/ Cardiff Uni | Hours: 11.0
A375: Geoff Malpas|2026-07-14 | B375: 46217 | C375: Geoff Malpas | D375: Permanent | E375: Bristol | F375: Operative Porter | G375: 402750 | H375: Barbican/ Cardiff Uni | I375: 9.5 | J375: Worked | K375: Worked: 1 record(s) | Branch: Bristol | Role: Operative Porter | Jobs: 402750 | Customers: Barbican/ Cardiff Uni | Hours: 9.5
A376: Greg Georgiou|2026-07-01 | B376: 46204 | C376: Greg Georgiou | D376: Permanent | E376: Bristol | F376: Operative Skilled | G376: 402832 | H376: University of Bristol - Queens Road | I376: 8.5 | J376: Worked | K376: Worked: 1 record(s) | Branch: Bristol | Role: Operative Skilled | Jobs: 402832 | Customers: University of Bristol - Queens Road | Hours: 8.5
A377: Greg Georgiou|2026-07-02 | B377: 46205 | C377: Greg Georgiou | D377: Permanent | E377: Bristol | F377: Operative Skilled | G377: 402832 | H377: University of Bristol - Queens Road | I377: 8 | J377: Worked | K377: Worked: 1 record(s) | Branch: Bristol | Role: Operative Skilled | Jobs: 402832 | Customers: University of Bristol - Queens Road | Hours: 8.0
A378: Greg Georgiou|2026-07-03 | B378: 46206 | C378: Greg Georgiou | D378: Permanent | E378: Thurrock | F378: Operative Porter | G378: 402287 | H378: Accenture UK Ltd | I378: 16 | J378: Worked | K378: Worked: 1 record(s) | Branch: Thurrock | Role: Operative Porter | Jobs: 402287 | Customers: Accenture UK Ltd | Hours: 16.0
A379: Greg Georgiou|2026-07-04 | B379: 46207 | C379: Greg Georgiou | D379: Permanent | E379: Thurrock | F379: Operative Driver | G379: 402287 | H379: Accenture UK Ltd | I379: 8 | J379: Worked | K379: Worked: 1 record(s) | Branch: Thurrock | Role: Operative Driver | Jobs: 402287 | Customers: Accenture UK Ltd | Hours: 8.0
A380: Greg Georgiou|2026-07-06 | B380: 46209 | C380: Greg Georgiou | D380: Permanent | E380: Thurrock | F380: Operative Driver | G380: 402287 | H380: Accenture UK Ltd | I380: 8 | J380: Worked | K380: Worked: 1 record(s) | Branch: Thurrock | Role: Operative Driver | Jobs: 402287 | Customers: Accenture UK Ltd | Hours: 8.0
A381: Greg Georgiou|2026-07-07 | B381: 46210 | C381: Greg Georgiou | D381: Permanent | E381: Cambridge | F381: Operative Skilled | G381: 403004E | H381: Avantor (BRISTOL JULY 2026 ) | I381: 6 | J381: Worked | K381: Worked: 1 record(s) | Branch: Cambridge | Role: Operative Skilled | Jobs: 403004E | Customers: Avantor (BRISTOL JULY 2026 ) | Hours: 6.0
A382: Greg Georgiou|2026-07-09 | B382: 46212 | C382: Greg Georgiou | D382: Permanent | E382: Bristol | F382: Operative Skilled | G382: 398973 | H382: UWE - Northavon House | I382: 9.5 | J382: Worked | K382: Worked: 1 record(s) | Branch: Bristol | Role: Operative Skilled | Jobs: 398973 | Customers: UWE - Northavon House | Hours: 9.5
...

Sheet Individual Activity
A1: Individual Activity Calendar
A3: Person | B3: M Palmer (B) | D3: Period Start | E3: 46082 | G3: 46112 | H3: 46219
A5: Monday | B5: Tuesday | C5: Wednesday | D5: Thursday | E5: Friday | F5: Saturday | G5: Sunday
A6: =IF(OR(AH6<$E$3,AH6>$H$3),"",TEXT(AH6,"d mmm")&CHAR(10)&IFERROR(VLOOKUP($B$3&"|"&TEXT(AH6,"yyyy-mm-dd"),'Activity Daily Summary'!$A$4:$K$1254,10,FALSE),"No recorded activity")) | B6: =IF(OR(AI6<$E$3,AI6>$H$3),"",TEXT(AI6,"d mmm")&CHAR(10)&IFERROR(VLOOKUP($B$3&"|"&TEXT(AI6,"yyyy-mm-dd"),'Activity Daily Summary'!$A$4:$K$1254,10,FALSE),"No recorded activity")) | C6: =IF(OR(AJ6<$E$3,AJ6>$H$3),"",TEXT(AJ6,"d mmm")&CHAR(10)&IFERROR(VLOOKUP($B$3&"|"&TEXT(AJ6,"yyyy-mm-dd"),'Activity Daily Summary'!$A$4:$K$1254,10,FALSE),"No recorded activity")) | D6: =IF(OR(AK6<$E$3,AK6>$H$3),"",TEXT(AK6,"d mmm")&CHAR(10)&IFERROR(VLOOKUP($B$3&"|"&TEXT(AK6,"yyyy-mm-dd"),'Activity Daily Summary'!$A$4:$K$1254,10,FALSE),"No recorded activity")) | E6: =IF(OR(AL6<$E$3,AL6>$H$3),"",TEXT(AL6,"d mmm")&CHAR(10)&IFERROR(VLOOKUP($B$3&"|"&TEXT(AL6,"yyyy-mm-dd"),'Activity Daily Summary'!$A$4:$K$1254,10,FALSE),"No recorded activity")) | F6: =IF(OR(AM6<$E$3,AM6>$H$3),"",TEXT(AM6,"d mmm")&CHAR(10)&IFERROR(VLOOKUP($B$3&"|"&TEXT(AM6,"yyyy-mm-dd"),'Activity Daily Summary'!$A$4:$K$1254,10,FALSE),"No recorded activity")) | G6: =IF(OR(AN6<$E$3,AN6>$H$3),"",TEXT(AN6,"d mmm")&CHAR(10)&IFERROR(VLOOKUP($B$3&"|"&TEXT(AN6,"yyyy-mm-dd"),'Activity Daily Summary'!$A$4:$K$1254,10,FALSE),"No recorded activity")) -> 1 Mar No recorded activity | AH6: =$E$3-WEEKDAY($E$3,2)+1+0 -> 46076 | AI6: =$E$3-WEEKDAY($E$3,2)+1+1 -> 46077 | AJ6: =$E$3-WEEKDAY($E$3,2)+1+2 -> 46078 | AK6: =$E$3-WEEKDAY($E$3,2)+1+3 -> 46079 | AL6: =$E$3-WEEKDAY($E$3,2)+1+4 -> 46080 | AM6: =$E$3-WEEKDAY($E$3,2)+1+5 -> 46081 | AN6: =$E$3-WEEKDAY($E$3,2)+1+6 -> 46082
A7: =IF(OR(AH7<$E$3,AH7>$H$3),"",TEXT(AH7,"d mmm")&CHAR(10)&IFERROR(VLOOKUP($B$3&"|"&TEXT(AH7,"yyyy-mm-dd"),'Activity Daily Summary'!$A$4:$K$1254,10,FALSE),"No recorded activity")) -> 2 Mar No recorded activity | B7: =IF(OR(AI7<$E$3,AI7>$H$3),"",TEXT(AI7,"d mmm")&CHAR(10)&IFERROR(VLOOKUP($B$3&"|"&TEXT(AI7,"yyyy-mm-dd"),'Activity Daily Summary'!$A$4:$K$1254,10,FALSE),"No recorded activity")) -> 3 Mar No recorded activity | C7: =IF(OR(AJ7<$E$3,AJ7>$H$3),"",TEXT(AJ7,"d mmm")&CHAR(10)&IFERROR(VLOOKUP($B$3&"|"&TEXT(AJ7,"yyyy-mm-dd"),'Activity Daily Summary'!$A$4:$K$1254,10,FALSE),"No recorded activity")) -> 4 Mar No recorded activity | D7: =IF(OR(AK7<$E$3,AK7>$H$3),"",TEXT(AK7,"d mmm")&CHAR(10)&IFERROR(VLOOKUP($B$3&"|"&TEXT(AK7,"yyyy-mm-dd"),'Activity Daily Summary'!$A$4:$K$1254,10,FALSE),"No recorded activity")) -> 5 Mar No recorded activity | E7: =IF(OR(AL7<$E$3,AL7>$H$3),"",TEXT(AL7,"d mmm")&CHAR(10)&IFERROR(VLOOKUP($B$3&"|"&TEXT(AL7,"yyyy-mm-dd"),'Activity Daily Summary'!$A$4:$K$1254,10,FALSE),"No recorded activity")) -> 6 Mar No recorded activity | F7: =IF(OR(AM7<$E$3,AM7>$H$3),"",TEXT(AM7,"d mmm")&CHAR(10)&IFERROR(VLOOKUP($B$3&"|"&TEXT(AM7,"yyyy-mm-dd"),'Activity Daily Summary'!$A$4:$K$1254,10,FALSE),"No recorded activity")) -> 7 Mar No recorded activity | G7: =IF(OR(AN7<$E$3,AN7>$H$3),"",TEXT(AN7,"d mmm")&CHAR(10)&IFERROR(VLOOKUP($B$3&"|"&TEXT(AN7,"yyyy-mm-dd"),'Activity Daily Summary'!$A$4:$K$1254,10,FALSE),"No recorded activity")) -> 8 Mar No recorded activity | AH7: =$E$3-WEEKDAY($E$3,2)+1+7 -> 46083 | AI7: =$E$3-WEEKDAY($E$3,2)+1+8 -> 46084 | AJ7: =$E$3-WEEKDAY($E$3,2)+1+9 -> 46085 | AK7: =$E$3-WEEKDAY($E$3,2)+1+10 -> 46086 | AL7: =$E$3-WEEKDAY($E$3,2)+1+11 -> 46087 | AM7: =$E$3-WEEKDAY($E$3,2)+1+12 -> 46088 | AN7: =$E$3-WEEKDAY($E$3,2)+1+13 -> 46089
A8: =IF(OR(AH8<$E$3,AH8>$H$3),"",TEXT(AH8,"d mmm")&CHAR(10)&IFERROR(VLOOKUP($B$3&"|"&TEXT(AH8,"yyyy-mm-dd"),'Activity Daily Summary'!$A$4:$K$1254,10,FALSE),"No recorded activity")) -> 9 Mar No recorded activity | B8: =IF(OR(AI8<$E$3,AI8>$H$3),"",TEXT(AI8,"d mmm")&CHAR(10)&IFERROR(VLOOKUP($B$3&"|"&TEXT(AI8,"yyyy-mm-dd"),'Activity Daily Summary'!$A$4:$K$1254,10,FALSE),"No recorded activity")) -> 10 Mar No recorded activity | C8: =IF(OR(AJ8<$E$3,AJ8>$H$3),"",TEXT(AJ8,"d mmm")&CHAR(10)&IFERROR(VLOOKUP($B$3&"|"&TEXT(AJ8,"yyyy-mm-dd"),'Activity Daily Summary'!$A$4:$K$1254,10,FALSE),"No recorded activity")) -> 11 Mar No recorded activity | D8: =IF(OR(AK8<$E$3,AK8>$H$3),"",TEXT(AK8,"d mmm")&CHAR(10)&IFERROR(VLOOKUP($B$3&"|"&TEXT(AK8,"yyyy-mm-dd"),'Activity Daily Summary'!$A$4:$K$1254,10,FALSE),"No recorded activity")) -> 12 Mar No recorded activity | E8: =IF(OR(AL8<$E$3,AL8>$H$3),"",TEXT(AL8,"d mmm")&CHAR(10)&IFERROR(VLOOKUP($B$3&"|"&TEXT(AL8,"yyyy-mm-dd"),'Activity Daily Summary'!$A$4:$K$1254,10,FALSE),"No recorded activity")) -> 13 Mar No recorded activity | F8: =IF(OR(AM8<$E$3,AM8>$H$3),"",TEXT(AM8,"d mmm")&CHAR(10)&IFERROR(VLOOKUP($B$3&"|"&TEXT(AM8,"yyyy-mm-dd"),'Activity Daily Summary'!$A$4:$K$1254,10,FALSE),"No recorded activity")) -> 14 Mar No recorded activity | G8: =IF(OR(AN8<$E$3,AN8>$H$3),"",TEXT(AN8,"d mmm")&CHAR(10)&IFERROR(VLOOKUP($B$3&"|"&TEXT(AN8,"yyyy-mm-dd"),'Activity Daily Summary'!$A$4:$K$1254,10,FALSE),"No recorded activity")) -> 15 Mar No recorded activity | AH8: =$E$3-WEEKDAY($E$3,2)+1+14 -> 46090 | AI8: =$E$3-WEEKDAY($E$3,2)+1+15 -> 46091 | AJ8: =$E$3-WEEKDAY($E$3,2)+1+16 -> 46092 | AK8: =$E$3-WEEKDAY($E$3,2)+1+17 -> 46093 | AL8: =$E$3-WEEKDAY($E$3,2)+1+18 -> 46094 | AM8: =$E$3-WEEKDAY($E$3,2)+1+19 -> 46095 | AN8: =$E$3-WEEKDAY($E$3,2)+1+20 -> 46096
A9: =IF(OR(AH9<$E$3,AH9>$H$3),"",TEXT(AH9,"d mmm")&CHAR(10)&IFERROR(VLOOKUP($B$3&"|"&TEXT(AH9,"yyyy-mm-dd"),'Activity Daily Summary'!$A$4:$K$1254,10,FALSE),"No recorded activity")) -> 16 Mar No recorded activity | B9: =IF(OR(AI9<$E$3,AI9>$H$3),"",TEXT(AI9,"d mmm")&CHAR(10)&IFERROR(VLOOKUP($B$3&"|"&TEXT(AI9,"yyyy-mm-dd"),'Activity Daily Summary'!$A$4:$K$1254,10,FALSE),"No recorded activity")) -> 17 Mar No recorded activity | C9: =IF(OR(AJ9<$E$3,AJ9>$H$3),"",TEXT(AJ9,"d mmm")&CHAR(10)&IFERROR(VLOOKUP($B$3&"|"&TEXT(AJ9,"yyyy-mm-dd"),'Activity Daily Summary'!$A$4:$K$1254,10,FALSE),"No recorded activity")) -> 18 Mar No recorded activity | D9: =IF(OR(AK9<$E$3,AK9>$H$3),"",TEXT(AK9,"d mmm")&CHAR(10)&IFERROR(VLOOKUP($B$3&"|"&TEXT(AK9,"yyyy-mm-dd"),'Activity Daily Summary'!$A$4:$K$1254,10,FALSE),"No recorded activity")) -> 19 Mar No recorded activity | E9: =IF(OR(AL9<$E$3,AL9>$H$3),"",TEXT(AL9,"d mmm")&CHAR(10)&IFERROR(VLOOKUP($B$3&"|"&TEXT(AL9,"yyyy-mm-dd"),'Activity Daily Summary'!$A$4:$K$1254,10,FALSE),"No recorded activity")) -> 20 Mar No recorded activity | F9: =IF(OR(AM9<$E$3,AM9>$H$3),"",TEXT(AM9,"d mmm")&CHAR(10)&IFERROR(VLOOKUP($B$3&"|"&TEXT(AM9,"yyyy-mm-dd"),'Activity Daily Summary'!$A$4:$K$1254,10,FALSE),"No recorded activity")) -> 21 Mar No recorded activity | G9: =IF(OR(AN9<$E$3,AN9>$H$3),"",TEXT(AN9,"d mmm")&CHAR(10)&IFERROR(VLOOKUP($B$3&"|"&TEXT(AN9,"yyyy-mm-dd"),'Activity Daily Summary'!$A$4:$K$1254,10,FALSE),"No recorded activity")) -> 22 Mar No recorded activity | AH9: =$E$3-WEEKDAY($E$3,2)+1+21 -> 46097 | AI9: =$E$3-WEEKDAY($E$3,2)+1+22 -> 46098 | AJ9: =$E$3-WEEKDAY($E$3,2)+1+23 -> 46099 | AK9: =$E$3-WEEKDAY($E$3,2)+1+24 -> 46100 | AL9: =$E$3-WEEKDAY($E$3,2)+1+25 -> 46101 | AM9: =$E$3-WEEKDAY($E$3,2)+1+26 -> 46102 | AN9: =$E$3-WEEKDAY($E$3,2)+1+27 -> 46103
A10: =IF(OR(AH10<$E$3,AH10>$H$3),"",TEXT(AH10,"d mmm")&CHAR(10)&IFERROR(VLOOKUP($B$3&"|"&TEXT(AH10,"yyyy-mm-dd"),'Activity Daily Summary'!$A$4:$K$1254,10,FALSE),"No recorded activity")) -> 23 Mar No recorded activity | B10: =IF(OR(AI10<$E$3,AI10>$H$3),"",TEXT(AI10,"d mmm")&CHAR(10)&IFERROR(VLOOKUP($B$3&"|"&TEXT(AI10,"yyyy-mm-dd"),'Activity Daily Summary'!$A$4:$K$1254,10,FALSE),"No recorded activity")) -> 24 Mar No recorded activity | C10: =IF(OR(AJ10<$E$3,AJ10>$H$3),"",TEXT(AJ10,"d mmm")&CHAR(10)&IFERROR(VLOOKUP($B$3&"|"&TEXT(AJ10,"yyyy-mm-dd"),'Activity Daily Summary'!$A$4:$K$1254,10,FALSE),"No recorded activity")) -> 25 Mar No recorded activity | D10: =IF(OR(AK10<$E$3,AK10>$H$3),"",TEXT(AK10,"d mmm")&CHAR(10)&IFERROR(VLOOKUP($B$3&"|"&TEXT(AK10,"yyyy-mm-dd"),'Activity Daily Summary'!$A$4:$K$1254,10,FALSE),"No recorded activity")) -> 26 Mar No recorded activity | E10: =IF(OR(AL10<$E$3,AL10>$H$3),"",TEXT(AL10,"d mmm")&CHAR(10)&IFERROR(VLOOKUP($B$3&"|"&TEXT(AL10,"yyyy-mm-dd"),'Activity Daily Summary'!$A$4:$K$1254,10,FALSE),"No recorded activity")) -> 27 Mar No recorded activity | F10: =IF(OR(AM10<$E$3,AM10>$H$3),"",TEXT(AM10,"d mmm")&CHAR(10)&IFERROR(VLOOKUP($B$3&"|"&TEXT(AM10,"yyyy-mm-dd"),'Activity Daily Summary'!$A$4:$K$1254,10,FALSE),"No recorded activity")) -> 28 Mar No recorded activity | G10: =IF(OR(AN10<$E$3,AN10>$H$3),"",TEXT(AN10,"d mmm")&CHAR(10)&IFERROR(VLOOKUP($B$3&"|"&TEXT(AN10,"yyyy-mm-dd"),'Activity Daily Summary'!$A$4:$K$1254,10,FALSE),"No recorded activity")) -> 29 Mar No recorded activity | AH10: =$E$3-WEEKDAY($E$3,2)+1+28 -> 46104 | AI10: =$E$3-WEEKDAY($E$3,2)+1+29 -> 46105 | AJ10: =$E$3-WEEKDAY($E$3,2)+1+30 -> 46106 | AK10: =$E$3-WEEKDAY($E$3,2)+1+31 -> 46107 | AL10: =$E$3-WEEKDAY($E$3,2)+1+32 -> 46108 | AM10: =$E$3-WEEKDAY($E$3,2)+1+33 -> 46109 | AN10: =$E$3-WEEKDAY($E$3,2)+1+34 -> 46110
A11: =IF(OR(AH11<$E$3,AH11>$H$3),"",TEXT(AH11,"d mmm")&CHAR(10)&IFERROR(VLOOKUP($B$3&"|"&TEXT(AH11,"yyyy-mm-dd"),'Activity Daily Summary'!$A$4:$K$1254,10,FALSE),"No recorded activity")) -> 30 Mar No recorded activity | B11: =IF(OR(AI11<$E$3,AI11>$H$3),"",TEXT(AI11,"d mmm")&CHAR(10)&IFERROR(VLOOKUP($B$3&"|"&TEXT(AI11,"yyyy-mm-dd"),'Activity Daily Summary'!$A$4:$K$1254,10,FALSE),"No recorded activity")) -> 31 Mar No recorded activity | C11: =IF(OR(AJ11<$E$3,AJ11>$H$3),"",TEXT(AJ11,"d mmm")&CHAR(10)&IFERROR(VLOOKUP($B$3&"|"&TEXT(AJ11,"yyyy-mm-dd"),'Activity Daily Summary'!$A$4:$K$1254,10,FALSE),"No recorded activity")) -> 1 Apr No recorded activity | D11: =IF(OR(AK11<$E$3,AK11>$H$3),"",TEXT(AK11,"d mmm")&CHAR(10)&IFERROR(VLOOKUP($B$3&"|"&TEXT(AK11,"yyyy-mm-dd"),'Activity Daily Summary'!$A$4:$K$1254,10,FALSE),"No recorded activity")) -> 2 Apr No recorded activity | E11: =IF(OR(AL11<$E$3,AL11>$H$3),"",TEXT(AL11,"d mmm")&CHAR(10)&IFERROR(VLOOKUP($B$3&"|"&TEXT(AL11,"yyyy-mm-dd"),'Activity Daily Summary'!$A$4:$K$1254,10,FALSE),"No recorded activity")) -> 3 Apr No recorded activity | F11: =IF(OR(AM11<$E$3,AM11>$H$3),"",TEXT(AM11,"d mmm")&CHAR(10)&IFERROR(VLOOKUP($B$3&"|"&TEXT(AM11,"yyyy-mm-dd"),'Activity Daily Summary'!$A$4:$K$1254,10,FALSE),"No recorded activity")) -> 4 Apr No recorded activity | G11: =IF(OR(AN11<$E$3,AN11>$H$3),"",TEXT(AN11,"d mmm")&CHAR(10)&IFERROR(VLOOKUP($B$3&"|"&TEXT(AN11,"yyyy-mm-dd"),'Activity Daily Summary'!$A$4:$K$1254,10,FALSE),"No recorded activity")) -> 5 Apr No recorded activity | AH11: =$E$3-WEEKDAY($E$3,2)+1+35 -> 46111 | AI11: =$E$3-WEEKDAY($E$3,2)+1+36 -> 46112 | AJ11: =$E$3-WEEKDAY($E$3,2)+1+37 -> 46113 | AK11: =$E$3-WEEKDAY($E$3,2)+1+38 -> 46114 | AL11: =$E$3-WEEKDAY($E$3,2)+1+39 -> 46115 | AM11: =$E$3-WEEKDAY($E$3,2)+1+40 -> 46116 | AN11: =$E$3-WEEKDAY($E$3,2)+1+41 -> 46117
A13: Daily Detail
A14: Date | B14: Day | C14: Activity | D14: Branch | E14: Role | F14: Jobs / Customers | G14: Actual Hours | H14: Full Detail
A15: =IF(0<=$H$3-$E$3,$E$3+0,"") -> 46082 | B15: =IF(A15="","",TEXT(A15,"ddd")) -> Sun | C15: =IF(A15="","",IFERROR(VLOOKUP($B$3&"|"&TEXT(A15,"yyyy-mm-dd"),'Activity Daily Summary'!$A$4:$K$1254,10,FALSE),"No recorded activity")) -> No recorded activity | D15: =IF(A15="","",IFERROR(VLOOKUP($B$3&"|"&TEXT(A15,"yyyy-mm-dd"),'Activity Daily Summary'!$A$4:$K$1254,5,FALSE),"")) | E15: =IF(A15="","",IFERROR(VLOOKUP($B$3&"|"&TEXT(A15,"yyyy-mm-dd"),'Activity Daily Summary'!$A$4:$K$1254,6,FALSE),"")) | F15: =IF(A15="","",IFERROR(VLOOKUP($B$3&"|"&TEXT(A15,"yyyy-mm-dd"),'Activity Daily Summary'!$A$4:$K$1254,7,FALSE)&IF(VLOOKUP($B$3&"|"&TEXT(A15,"yyyy-mm-dd"),'Activity Daily Summary'!$A$4:$K$1254,8,FALSE)="",""," — "&VLOOKUP($B$3&"|"&TEXT(A15,"yyyy-mm-dd"),'Activity Daily Summary'!$A$4:$K$1254,8,FALSE)),"")) | G15: =IF(A15="","",IFERROR(VLOOKUP($B$3&"|"&TEXT(A15,"yyyy-mm-dd"),'Activity Daily Summary'!$A$4:$K$1254,9,FALSE),0)) -> 0 | H15: =IF(A15="","",IFERROR(VLOOKUP($B$3&"|"&TEXT(A15,"yyyy-mm-dd"),'Activity Daily Summary'!$A$4:$K$1254,11,FALSE),"No recorded activity")) -> No recorded activity
A16: =IF(1<=$H$3-$E$3,$E$3+1,"") -> 46083 | B16: =IF(A16="","",TEXT(A16,"ddd")) -> Mon | C16: =IF(A16="","",IFERROR(VLOOKUP($B$3&"|"&TEXT(A16,"yyyy-mm-dd"),'Activity Daily Summary'!$A$4:$K$1254,10,FALSE),"No recorded activity")) -> No recorded activity | D16: =IF(A16="","",IFERROR(VLOOKUP($B$3&"|"&TEXT(A16,"yyyy-mm-dd"),'Activity Daily Summary'!$A$4:$K$1254,5,FALSE),"")) | E16: =IF(A16="","",IFERROR(VLOOKUP($B$3&"|"&TEXT(A16,"yyyy-mm-dd"),'Activity Daily Summary'!$A$4:$K$1254,6,FALSE),"")) | F16: =IF(A16="","",IFERROR(VLOOKUP($B$3&"|"&TEXT(A16,"yyyy-mm-dd"),'Activity Daily Summary'!$A$4:$K$1254,7,FALSE)&IF(VLOOKUP($B$3&"|"&TEXT(A16,"yyyy-mm-dd"),'Activity Daily Summary'!$A$4:$K$1254,8,FALSE)="",""," — "&VLOOKUP($B$3&"|"&TEXT(A16,"yyyy-mm-dd"),'Activity Daily Summary'!$A$4:$K$1254,8,FALSE)),"")) | G16: =IF(A16="","",IFERROR(VLOOKUP($B$3&"|"&TEXT(A16,"yyyy-mm-dd"),'Activity Daily Summary'!$A$4:$K$1254,9,FALSE),0)) -> 0 | H16: =IF(A16="","",IFERROR(VLOOKUP($B$3&"|"&TEXT(A16,"yyyy-mm-dd"),'Activity Daily Summary'!$A$4:$K$1254,11,FALSE),"No recorded activity")) -> No recorded activity
A17: =IF(2<=$H$3-$E$3,$E$3+2,"") -> 46084 | B17: =IF(A17="","",TEXT(A17,"ddd")) -> Tue | C17: =IF(A17="","",IFERROR(VLOOKUP($B$3&"|"&TEXT(A17,"yyyy-mm-dd"),'Activity Daily Summary'!$A$4:$K$1254,10,FALSE),"No recorded activity")) -> No recorded activity | D17: =IF(A17="","",IFERROR(VLOOKUP($B$3&"|"&TEXT(A17,"yyyy-mm-dd"),'Activity Daily Summary'!$A$4:$K$1254,5,FALSE),"")) | E17: =IF(A17="","",IFERROR(VLOOKUP($B$3&"|"&TEXT(A17,"yyyy-mm-dd"),'Activity Daily Summary'!$A$4:$K$1254,6,FALSE),"")) | F17: =IF(A17="","",IFERROR(VLOOKUP($B$3&"|"&TEXT(A17,"yyyy-mm-dd"),'Activity Daily Summary'!$A$4:$K$1254,7,FALSE)&IF(VLOOKUP($B$3&"|"&TEXT(A17,"yyyy-mm-dd"),'Activity Daily Summary'!$A$4:$K$1254,8,FALSE)="",""," — "&VLOOKUP($B$3&"|"&TEXT(A17,"yyyy-mm-dd"),'Activity Daily Summary'!$A$4:$K$1254,8,FALSE)),"")) | G17: =IF(A17="","",IFERROR(VLOOKUP($B$3&"|"&TEXT(A17,"yyyy-mm-dd"),'Activity Daily Summary'!$A$4:$K$1254,9,FALSE),0)) -> 0 | H17: =IF(A17="","",IFERROR(VLOOKUP($B$3&"|"&TEXT(A17,"yyyy-mm-dd"),'Activity Daily Summary'!$A$4:$K$1254,11,FALSE),"No recorded activity")) -> No recorded activity
A18: =IF(3<=$H$3-$E$3,$E$3+3,"") -> 46085 | B18: =IF(A18="","",TEXT(A18,"ddd")) -> Wed | C18: =IF(A18="","",IFERROR(VLOOKUP($B$3&"|"&TEXT(A18,"yyyy-mm-dd"),'Activity Daily Summary'!$A$4:$K$1254,10,FALSE),"No recorded activity")) -> No recorded activity | D18: =IF(A18="","",IFERROR(VLOOKUP($B$3&"|"&TEXT(A18,"yyyy-mm-dd"),'Activity Daily Summary'!$A$4:$K$1254,5,FALSE),"")) | E18: =IF(A18="","",IFERROR(VLOOKUP($B$3&"|"&TEXT(A18,"yyyy-mm-dd"),'Activity Daily Summary'!$A$4:$K$1254,6,FALSE),"")) | F18: =IF(A18="","",IFERROR(VLOOKUP($B$3&"|"&TEXT(A18,"yyyy-mm-dd"),'Activity Daily Summary'!$A$4:$K$1254,7,FALSE)&IF(VLOOKUP($B$3&"|"&TEXT(A18,"yyyy-mm-dd"),'Activity Daily Summary'!$A$4:$K$1254,8,FALSE)="",""," — "&VLOOKUP($B$3&"|"&TEXT(A18,"yyyy-mm-dd"),'Activity Daily Summary'!$A$4:$K$1254,8,FALSE)),"")) | G18: =IF(A18="","",IFERROR(VLOOKUP($B$3&"|"&TEXT(A18,"yyyy-mm-dd"),'Activity Daily Summary'!$A$4:$K$1254,9,FALSE),0)) -> 0 | H18: =IF(A18="","",IFERROR(VLOOKUP($B$3&"|"&TEXT(A18,"yyyy-mm-dd"),'Activity Daily Summary'!$A$4:$K$1254,11,FALSE),"No recorded activity")) -> No recorded activity
A19: =IF(4<=$H$3-$E$3,$E$3+4,"") -> 46086 | B19: =IF(A19="","",TEXT(A19,"ddd")) -> Thu | C19: =IF(A19="","",IFERROR(VLOOKUP($B$3&"|"&TEXT(A19,"yyyy-mm-dd"),'Activity Daily Summary'!$A$4:$K$1254,10,FALSE),"No recorded activity")) -> No recorded activity | D19: =IF(A19="","",IFERROR(VLOOKUP($B$3&"|"&TEXT(A19,"yyyy-mm-dd"),'Activity Daily Summary'!$A$4:$K$1254,5,FALSE),"")) | E19: =IF(A19="","",IFERROR(VLOOKUP($B$3&"|"&TEXT(A19,"yyyy-mm-dd"),'Activity Daily Summary'!$A$4:$K$1254,6,FALSE),"")) | F19: =IF(A19="","",IFERROR(VLOOKUP($B$3&"|"&TEXT(A19,"yyyy-mm-dd"),'Activity Daily Summary'!$A$4:$K$1254,7,FALSE)&IF(VLOOKUP($B$3&"|"&TEXT(A19,"yyyy-mm-dd"),'Activity Daily Summary'!$A$4:$K$1254,8,FALSE)="",""," — "&VLOOKUP($B$3&"|"&TEXT(A19,"yyyy-mm-dd"),'Activity Daily Summary'!$A$4:$K$1254,8,FALSE)),"")) | G19: =IF(A19="","",IFERROR(VLOOKUP($B$3&"|"&TEXT(A19,"yyyy-mm-dd"),'Activity Daily Summary'!$A$4:$K$1254,9,FALSE),0)) -> 0 | H19: =IF(A19="","",IFERROR(VLOOKUP($B$3&"|"&TEXT(A19,"yyyy-mm-dd"),'Activity Daily Summary'!$A$4:$K$1254,11,FALSE),"No recorded activity")) -> No recorded activity
A20: =IF(5<=$H$3-$E$3,$E$3+5,"") -> 46087 | B20: =IF(A20="","",TEXT(A20,"ddd")) -> Fri | C20: =IF(A20="","",IFERROR(VLOOKUP($B$3&"|"&TEXT(A20,"yyyy-mm-dd"),'Activity Daily Summary'!$A$4:$K$1254,10,FALSE),"No recorded activity")) -> No recorded activity | D20: =IF(A20="","",IFERROR(VLOOKUP($B$3&"|"&TEXT(A20,"yyyy-mm-dd"),'Activity Daily Summary'!$A$4:$K$1254,5,FALSE),"")) | E20: =IF(A20="","",IFERROR(VLOOKUP($B$3&"|"&TEXT(A20,"yyyy-mm-dd"),'Activity Daily Summary'!$A$4:$K$1254,6,FALSE),"")) | F20: =IF(A20="","",IFERROR(VLOOKUP($B$3&"|"&TEXT(A20,"yyyy-mm-dd"),'Activity Daily Summary'!$A$4:$K$1254,7,FALSE)&IF(VLOOKUP($B$3&"|"&TEXT(A20,"yyyy-mm-dd"),'Activity Daily Summary'!$A$4:$K$1254,8,FALSE)="",""," — "&VLOOKUP($B$3&"|"&TEXT(A20,"yyyy-mm-dd"),'Activity Daily Summary'!$A$4:$K$1254,8,FALSE)),"")) | G20: =IF(A20="","",IFERROR(VLOOKUP($B$3&"|"&TEXT(A20,"yyyy-mm-dd"),'Activity Daily Summary'!$A$4:$K$1254,9,FALSE),0)) -> 0 | H20: =IF(A20="","",IFERROR(VLOOKUP($B$3&"|"&TEXT(A20,"yyyy-mm-dd"),'Activity Daily Summary'!$A$4:$K$1254,11,FALSE),"No recorded activity")) -> No recorded activity
A21: =IF(6<=$H$3-$E$3,$E$3+6,"") -> 46088 | B21: =IF(A21="","",TEXT(A21,"ddd")) -> Sat | C21: =IF(A21="","",IFERROR(VLOOKUP($B$3&"|"&TEXT(A21,"yyyy-mm-dd"),'Activity Daily Summary'!$A$4:$K$1254,10,FALSE),"No recorded activity")) -> No recorded activity | D21: =IF(A21="","",IFERROR(VLOOKUP($B$3&"|"&TEXT(A21,"yyyy-mm-dd"),'Activity Daily Summary'!$A$4:$K$1254,5,FALSE),"")) | E21: =IF(A21="","",IFERROR(VLOOKUP($B$3&"|"&TEXT(A21,"yyyy-mm-dd"),'Activity Daily Summary'!$A$4:$K$1254,6,FALSE),"")) | F21: =IF(A21="","",IFERROR(VLOOKUP($B$3&"|"&TEXT(A21,"yyyy-mm-dd"),'Activity Daily Summary'!$A$4:$K$1254,7,FALSE)&IF(VLOOKUP($B$3&"|"&TEXT(A21,"yyyy-mm-dd"),'Activity Daily Summary'!$A$4:$K$1254,8,FALSE)="",""," — "&VLOOKUP($B$3&"|"&TEXT(A21,"yyyy-mm-dd"),'Activity Daily Summary'!$A$4:$K$1254,8,FALSE)),"")) | G21: =IF(A21="","",IFERROR(VLOOKUP($B$3&"|"&TEXT(A21,"yyyy-mm-dd"),'Activity Daily Summary'!$A$4:$K$1254,9,FALSE),0)) -> 0 | H21: =IF(A21="","",IFERROR(VLOOKUP($B$3&"|"&TEXT(A21,"yyyy-mm-dd"),'Activity Daily Summary'!$A$4:$K$1254,11,FALSE),"No recorded activity")) -> No recorded activity
A22: =IF(7<=$H$3-$E$3,$E$3+7,"") -> 46089 | B22: =IF(A22="","",TEXT(A22,"ddd")) -> Sun | C22: =IF(A22="","",IFERROR(VLOOKUP($B$3&"|"&TEXT(A22,"yyyy-mm-dd"),'Activity Daily Summary'!$A$4:$K$1254,10,FALSE),"No recorded activity")) -> No recorded activity | D22: =IF(A22="","",IFERROR(VLOOKUP($B$3&"|"&TEXT(A22,"yyyy-mm-dd"),'Activity Daily Summary'!$A$4:$K$1254,5,FALSE),"")) | E22: =IF(A22="","",IFERROR(VLOOKUP($B$3&"|"&TEXT(A22,"yyyy-mm-dd"),'Activity Daily Summary'!$A$4:$K$1254,6,FALSE),"")) | F22: =IF(A22="","",IFERROR(VLOOKUP($B$3&"|"&TEXT(A22,"yyyy-mm-dd"),'Activity Daily Summary'!$A$4:$K$1254,7,FALSE)&IF(VLOOKUP($B$3&"|"&TEXT(A22,"yyyy-mm-dd"),'Activity Daily Summary'!$A$4:$K$1254,8,FALSE)="",""," — "&VLOOKUP($B$3&"|"&TEXT(A22,"yyyy-mm-dd"),'Activity Daily Summary'!$A$4:$K$1254,8,FALSE)),"")) | G22: =IF(A22="","",IFERROR(VLOOKUP($B$3&"|"&TEXT(A22,"yyyy-mm-dd"),'Activity Daily Summary'!$A$4:$K$1254,9,FALSE),0)) -> 0 | H22: =IF(A22="","",IFERROR(VLOOKUP($B$3&"|"&TEXT(A22,"yyyy-mm-dd"),'Activity Daily Summary'!$A$4:$K$1254,11,FALSE),"No recorded activity")) -> No recorded activity
A23: =IF(8<=$H$3-$E$3,$E$3+8,"") -> 46090 | B23: =IF(A23="","",TEXT(A23,"ddd")) -> Mon | C23: =IF(A23="","",IFERROR(VLOOKUP($B$3&"|"&TEXT(A23,"yyyy-mm-dd"),'Activity Daily Summary'!$A$4:$K$1254,10,FALSE),"No recorded activity")) -> No recorded activity | D23: =IF(A23="","",IFERROR(VLOOKUP($B$3&"|"&TEXT(A23,"yyyy-mm-dd"),'Activity Daily Summary'!$A$4:$K$1254,5,FALSE),"")) | E23: =IF(A23="","",IFERROR(VLOOKUP($B$3&"|"&TEXT(A23,"yyyy-mm-dd"),'Activity Daily Summary'!$A$4:$K$1254,6,FALSE),"")) | F23: =IF(A23="","",IFERROR(VLOOKUP($B$3&"|"&TEXT(A23,"yyyy-mm-dd"),'Activity Daily Summary'!$A$4:$K$1254,7,FALSE)&IF(VLOOKUP($B$3&"|"&TEXT(A23,"yyyy-mm-dd"),'Activity Daily Summary'!$A$4:$K$1254,8,FALSE)="",""," — "&VLOOKUP($B$3&"|"&TEXT(A23,"yyyy-mm-dd"),'Activity Daily Summary'!$A$4:$K$1254,8,FALSE)),"")) | G23: =IF(A23="","",IFERROR(VLOOKUP($B$3&"|"&TEXT(A23,"yyyy-mm-dd"),'Activity Daily Summary'!$A$4:$K$1254,9,FALSE),0)) -> 0 | H23: =IF(A23="","",IFERROR(VLOOKUP($B$3&"|"&TEXT(A23,"yyyy-mm-dd"),'Activity Daily Summary'!$A$4:$K$1254,11,FALSE),"No recorded activity")) -> No recorded activity
A24: =IF(9<=$H$3-$E$3,$E$3+9,"") -> 46091 | B24: =IF(A24="","",TEXT(A24,"ddd")) -> Tue | C24: =IF(A24="","",IFERROR(VLOOKUP($B$3&"|"&TEXT(A24,"yyyy-mm-dd"),'Activity Daily Summary'!$A$4:$K$1254,10,FALSE),"No recorded activity")) -> No recorded activity | D24: =IF(A24="","",IFERROR(VLOOKUP($B$3&"|"&TEXT(A24,"yyyy-mm-dd"),'Activity Daily Summary'!$A$4:$K$1254,5,FALSE),"")) | E24: =IF(A24="","",IFERROR(VLOOKUP($B$3&"|"&TEXT(A24,"yyyy-mm-dd"),'Activity Daily Summary'!$A$4:$K$1254,6,FALSE),"")) | F24: =IF(A24="","",IFERROR(VLOOKUP($B$3&"|"&TEXT(A24,"yyyy-mm-dd"),'Activity Daily Summary'!$A$4:$K$1254,7,FALSE)&IF(VLOOKUP($B$3&"|"&TEXT(A24,"yyyy-mm-dd"),'Activity Daily Summary'!$A$4:$K$1254,8,FALSE)="",""," — "&VLOOKUP($B$3&"|"&TEXT(A24,"yyyy-mm-dd"),'Activity Daily Summary'!$A$4:$K$1254,8,FALSE)),"")) | G24: =IF(A24="","",IFERROR(VLOOKUP($B$3&"|"&TEXT(A24,"yyyy-mm-dd"),'Activity Daily Summary'!$A$4:$K$1254,9,FALSE),0)) -> 0 | H24: =IF(A24="","",IFERROR(VLOOKUP($B$3&"|"&TEXT(A24,"yyyy-mm-dd"),'Activity Daily Summary'!$A$4:$K$1254,11,FALSE),"No recorded activity")) -> No recorded activity
A25: =IF(10<=$H$3-$E$3,$E$3+10,"") -> 46092 | B25: =IF(A25="","",TEXT(A25,"ddd")) -> Wed | C25: =IF(A25="","",IFERROR(VLOOKUP($B$3&"|"&TEXT(A25,"yyyy-mm-dd"),'Activity Daily Summary'!$A$4:$K$1254,10,FALSE),"No recorded activity")) -> No recorded activity | D25: =IF(A25="","",IFERROR(VLOOKUP($B$3&"|"&TEXT(A25,"yyyy-mm-dd"),'Activity Daily Summary'!$A$4:$K$1254,5,FALSE),"")) | E25: =IF(A25="","",IFERROR(VLOOKUP($B$3&"|"&TEXT(A25,"yyyy-mm-dd"),'Activity Daily Summary'!$A$4:$K$1254,6,FALSE),"")) | F25: =IF(A25="","",IFERROR(VLOOKUP($B$3&"|"&TEXT(A25,"yyyy-mm-dd"),'Activity Daily Summary'!$A$4:$K$1254,7,FALSE)&IF(VLOOKUP($B$3&"|"&TEXT(A25,"yyyy-mm-dd"),'Activity Daily Summary'!$A$4:$K$1254,8,FALSE)="",""," — "&VLOOKUP($B$3&"|"&TEXT(A25,"yyyy-mm-dd"),'Activity Daily Summary'!$A$4:$K$1254,8,FALSE)),"")) | G25: =IF(A25="","",IFERROR(VLOOKUP($B$3&"|"&TEXT(A25,"yyyy-mm-dd"),'Activity Daily Summary'!$A$4:$K$1254,9,FALSE),0)) -> 0 | H25: =IF(A25="","",IFERROR(VLOOKUP($B$3&"|"&TEXT(A25,"yyyy-mm-dd"),'Activity Daily Summary'!$A$4:$K$1254,11,FALSE),"No recorded activity")) -> No recorded activity
A26: =IF(11<=$H$3-$E$3,$E$3+11,"") -> 46093 | B26: =IF(A26="","",TEXT(A26,"ddd")) -> Thu | C26: =IF(A26="","",IFERROR(VLOOKUP($B$3&"|"&TEXT(A26,"yyyy-mm-dd"),'Activity Daily Summary'!$A$4:$K$1254,10,FALSE),"No recorded activity")) -> No recorded activity | D26: =IF(A26="","",IFERROR(VLOOKUP($B$3&"|"&TEXT(A26,"yyyy-mm-dd"),'Activity Daily Summary'!$A$4:$K$1254,5,FALSE),"")) | E26: =IF(A26="","",IFERROR(VLOOKUP($B$3&"|"&TEXT(A26,"yyyy-mm-dd"),'Activity Daily Summary'!$A$4:$K$1254,6,FALSE),"")) | F26: =IF(A26="","",IFERROR(VLOOKUP($B$3&"|"&TEXT(A26,"yyyy-mm-dd"),'Activity Daily Summary'!$A$4:$K$1254,7,FALSE)&IF(VLOOKUP($B$3&"|"&TEXT(A26,"yyyy-mm-dd"),'Activity Daily Summary'!$A$4:$K$1254,8,FALSE)="",""," — "&VLOOKUP($B$3&"|"&TEXT(A26,"yyyy-mm-dd"),'Activity Daily Summary'!$A$4:$K$1254,8,FALSE)),"")) | G26: =IF(A26="","",IFERROR(VLOOKUP($B$3&"|"&TEXT(A26,"yyyy-mm-dd"),'Activity Daily Summary'!$A$4:$K$1254,9,FALSE),0)) -> 0 | H26: =IF(A26="","",IFERROR(VLOOKUP($B$3&"|"&TEXT(A26,"yyyy-mm-dd"),'Activity Daily Summary'!$A$4:$K$1254,11,FALSE),"No recorded activity")) -> No recorded activity
A27: =IF(12<=$H$3-$E$3,$E$3+12,"") -> 46094 | B27: =IF(A27="","",TEXT(A27,"ddd")) -> Fri | C27: =IF(A27="","",IFERROR(VLOOKUP($B$3&"|"&TEXT(A27,"yyyy-mm-dd"),'Activity Daily Summary'!$A$4:$K$1254,10,FALSE),"No recorded activity")) -> No recorded activity | D27: =IF(A27="","",IFERROR(VLOOKUP($B$3&"|"&TEXT(A27,"yyyy-mm-dd"),'Activity Daily Summary'!$A$4:$K$1254,5,FALSE),"")) | E27: =IF(A27="","",IFERROR(VLOOKUP($B$3&"|"&TEXT(A27,"yyyy-mm-dd"),'Activity Daily Summary'!$A$4:$K$1254,6,FALSE),"")) | F27: =IF(A27="","",IFERROR(VLOOKUP($B$3&"|"&TEXT(A27,"yyyy-mm-dd"),'Activity Daily Summary'!$A$4:$K$1254,7,FALSE)&IF(VLOOKUP($B$3&"|"&TEXT(A27,"yyyy-mm-dd"),'Activity Daily Summary'!$A$4:$K$1254,8,FALSE)="",""," — "&VLOOKUP($B$3&"|"&TEXT(A27,"yyyy-mm-dd"),'Activity Daily Summary'!$A$4:$K$1254,8,FALSE)),"")) | G27: =IF(A27="","",IFERROR(VLOOKUP($B$3&"|"&TEXT(A27,"yyyy-mm-dd"),'Activity Daily Summary'!$A$4:$K$1254,9,FALSE),0)) -> 0 | H27: =IF(A27="","",IFERROR(VLOOKUP($B$3&"|"&TEXT(A27,"yyyy-mm-dd"),'Activity Daily Summary'!$A$4:$K$1254,11,FALSE),"No recorded activity")) -> No recorded activity
A28: =IF(13<=$H$3-$E$3,$E$3+13,"") -> 46095 | B28: =IF(A28="","",TEXT(A28,"ddd")) -> Sat | C28: =IF(A28="","",IFERROR(VLOOKUP($B$3&"|"&TEXT(A28,"yyyy-mm-dd"),'Activity Daily Summary'!$A$4:$K$1254,10,FALSE),"No recorded activity")) -> No recorded activity | D28: =IF(A28="","",IFERROR(VLOOKUP($B$3&"|"&TEXT(A28,"yyyy-mm-dd"),'Activity Daily Summary'!$A$4:$K$1254,5,FALSE),"")) | E28: =IF(A28="","",IFERROR(VLOOKUP($B$3&"|"&TEXT(A28,"yyyy-mm-dd"),'Activity Daily Summary'!$A$4:$K$1254,6,FALSE),"")) | F28: =IF(A28="","",IFERROR(VLOOKUP($B$3&"|"&TEXT(A28,"yyyy-mm-dd"),'Activity Daily Summary'!$A$4:$K$1254,7,FALSE)&IF(VLOOKUP($B$3&"|"&TEXT(A28,"yyyy-mm-dd"),'Activity Daily Summary'!$A$4:$K$1254,8,FALSE)="",""," — "&VLOOKUP($B$3&"|"&TEXT(A28,"yyyy-mm-dd"),'Activity Daily Summary'!$A$4:$K$1254,8,FALSE)),"")) | G28: =IF(A28="","",IFERROR(VLOOKUP($B$3&"|"&TEXT(A28,"yyyy-mm-dd"),'Activity Daily Summary'!$A$4:$K$1254,9,FALSE),0)) -> 0 | H28: =IF(A28="","",IFERROR(VLOOKUP($B$3&"|"&TEXT(A28,"yyyy-mm-dd"),'Activity Daily Summary'!$A$4:$K$1254,11,FALSE),"No recorded activity")) -> No recorded activity
A29: =IF(14<=$H$3-$E$3,$E$3+14,"") -> 46096 | B29: =IF(A29="","",TEXT(A29,"ddd")) -> Sun | C29: =IF(A29="","",IFERROR(VLOOKUP($B$3&"|"&TEXT(A29,"yyyy-mm-dd"),'Activity Daily Summary'!$A$4:$K$1254,10,FALSE),"No recorded activity")) -> No recorded activity | D29: =IF(A29="","",IFERROR(VLOOKUP($B$3&"|"&TEXT(A29,"yyyy-mm-dd"),'Activity Daily Summary'!$A$4:$K$1254,5,FALSE),"")) | E29: =IF(A29="","",IFERROR(VLOOKUP($B$3&"|"&TEXT(A29,"yyyy-mm-dd"),'Activity Daily Summary'!$A$4:$K$1254,6,FALSE),"")) | F29: =IF(A29="","",IFERROR(VLOOKUP($B$3&"|"&TEXT(A29,"yyyy-mm-dd"),'Activity Daily Summary'!$A$4:$K$1254,7,FALSE)&IF(VLOOKUP($B$3&"|"&TEXT(A29,"yyyy-mm-dd"),'Activity Daily Summary'!$A$4:$K$1254,8,FALSE)="",""," — "&VLOOKUP($B$3&"|"&TEXT(A29,"yyyy-mm-dd"),'Activity Daily Summary'!$A$4:$K$1254,8,FALSE)),"")) | G29: =IF(A29="","",IFERROR(VLOOKUP($B$3&"|"&TEXT(A29,"yyyy-mm-dd"),'Activity Daily Summary'!$A$4:$K$1254,9,FALSE),0)) -> 0 | H29: =IF(A29="","",IFERROR(VLOOKUP($B$3&"|"&TEXT(A29,"yyyy-mm-dd"),'Activity Daily Summary'!$A$4:$K$1254,11,FALSE),"No recorded activity")) -> No recorded activity
A30: =IF(15<=$H$3-$E$3,$E$3+15,"") -> 46097 | B30: =IF(A30="","",TEXT(A30,"ddd")) -> Mon | C30: =IF(A30="","",IFERROR(VLOOKUP($B$3&"|"&TEXT(A30,"yyyy-mm-dd"),'Activity Daily Summary'!$A$4:$K$1254,10,FALSE),"No recorded activity")) -> No recorded activity | D30: =IF(A30="","",IFERROR(VLOOKUP($B$3&"|"&TEXT(A30,"yyyy-mm-dd"),'Activity Daily Summary'!$A$4:$K$1254,5,FALSE),"")) | E30: =IF(A30="","",IFERROR(VLOOKUP($B$3&"|"&TEXT(A30,"yyyy-mm-dd"),'Activity Daily Summary'!$A$4:$K$1254,6,FALSE),"")) | F30: =IF(A30="","",IFERROR(VLOOKUP($B$3&"|"&TEXT(A30,"yyyy-mm-dd"),'Activity Daily Summary'!$A$4:$K$1254,7,FALSE)&IF(VLOOKUP($B$3&"|"&TEXT(A30,"yyyy-mm-dd"),'Activity Daily Summary'!$A$4:$K$1254,8,FALSE)="",""," — "&VLOOKUP($B$3&"|"&TEXT(A30,"yyyy-mm-dd"),'Activity Daily Summary'!$A$4:$K$1254,8,FALSE)),"")) | G30: =IF(A30="","",IFERROR(VLOOKUP($B$3&"|"&TEXT(A30,"yyyy-mm-dd"),'Activity Daily Summary'!$A$4:$K$1254,9,FALSE),0)) -> 0 | H30: =IF(A30="","",IFERROR(VLOOKUP($B$3&"|"&TEXT(A30,"yyyy-mm-dd"),'Activity Daily Summary'!$A$4:$K$1254,11,FALSE),"No recorded activity")) -> No recorded activity
A31: =IF(16<=$H$3-$E$3,$E$3+16,"") -> 46098 | B31: =IF(A31="","",TEXT(A31,"ddd")) -> Tue | C31: =IF(A31="","",IFERROR(VLOOKUP($B$3&"|"&TEXT(A31,"yyyy-mm-dd"),'Activity Daily Summary'!$A$4:$K$1254,10,FALSE),"No recorded activity")) -> No recorded activity | D31: =IF(A31="","",IFERROR(VLOOKUP($B$3&"|"&TEXT(A31,"yyyy-mm-dd"),'Activity Daily Summary'!$A$4:$K$1254,5,FALSE),"")) | E31: =IF(A31="","",IFERROR(VLOOKUP($B$3&"|"&TEXT(A31,"yyyy-mm-dd"),'Activity Daily Summary'!$A$4:$K$1254,6,FALSE),"")) | F31: =IF(A31="","",IFERROR(VLOOKUP($B$3&"|"&TEXT(A31,"yyyy-mm-dd"),'Activity Daily Summary'!$A$4:$K$1254,7,FALSE)&IF(VLOOKUP($B$3&"|"&TEXT(A31,"yyyy-mm-dd"),'Activity Daily Summary'!$A$4:$K$1254,8,FALSE)="",""," — "&VLOOKUP($B$3&"|"&TEXT(A31,"yyyy-mm-dd"),'Activity Daily Summary'!$A$4:$K$1254,8,FALSE)),"")) | G31: =IF(A31="","",IFERROR(VLOOKUP($B$3&"|"&TEXT(A31,"yyyy-mm-dd"),'Activity Daily Summary'!$A$4:$K$1254,9,FALSE),0)) -> 0 | H31: =IF(A31="","",IFERROR(VLOOKUP($B$3&"|"&TEXT(A31,"yyyy-mm-dd"),'Activity Daily Summary'!$A$4:$K$1254,11,FALSE),"No recorded activity")) -> No recorded activity
A32: =IF(17<=$H$3-$E$3,$E$3+17,"") -> 46099 | B32: =IF(A32="","",TEXT(A32,"ddd")) -> Wed | C32: =IF(A32="","",IFERROR(VLOOKUP($B$3&"|"&TEXT(A32,"yyyy-mm-dd"),'Activity Daily Summary'!$A$4:$K$1254,10,FALSE),"No recorded activity")) -> No recorded activity | D32: =IF(A32="","",IFERROR(VLOOKUP($B$3&"|"&TEXT(A32,"yyyy-mm-dd"),'Activity Daily Summary'!$A$4:$K$1254,5,FALSE),"")) | E32: =IF(A32="","",IFERROR(VLOOKUP($B$3&"|"&TEXT(A32,"yyyy-mm-dd"),'Activity Daily Summary'!$A$4:$K$1254,6,FALSE),"")) | F32: =IF(A32="","",IFERROR(VLOOKUP($B$3&"|"&TEXT(A32,"yyyy-mm-dd"),'Activity Daily Summary'!$A$4:$K$1254,7,FALSE)&IF(VLOOKUP($B$3&"|"&TEXT(A32,"yyyy-mm-dd"),'Activity Daily Summary'!$A$4:$K$1254,8,FALSE)="",""," — "&VLOOKUP($B$3&"|"&TEXT(A32,"yyyy-mm-dd"),'Activity Daily Summary'!$A$4:$K$1254,8,FALSE)),"")) | G32: =IF(A32="","",IFERROR(VLOOKUP($B$3&"|"&TEXT(A32,"yyyy-mm-dd"),'Activity Daily Summary'!$A$4:$K$1254,9,FALSE),0)) -> 0 | H32: =IF(A32="","",IFERROR(VLOOKUP($B$3&"|"&TEXT(A32,"yyyy-mm-dd"),'Activity Daily Summary'!$A$4:$K$1254,11,FALSE),"No recorded activity")) -> No recorded activity
A33: =IF(18<=$H$3-$E$3,$E$3+18,"") -> 46100 | B33: =IF(A33="","",TEXT(A33,"ddd")) -> Thu | C33: =IF(A33="","",IFERROR(VLOOKUP($B$3&"|"&TEXT(A33,"yyyy-mm-dd"),'Activity Daily Summary'!$A$4:$K$1254,10,FALSE),"No recorded activity")) -> No recorded activity | D33: =IF(A33="","",IFERROR(VLOOKUP($B$3&"|"&TEXT(A33,"yyyy-mm-dd"),'Activity Daily Summary'!$A$4:$K$1254,5,FALSE),"")) | E33: =IF(A33="","",IFERROR(VLOOKUP($B$3&"|"&TEXT(A33,"yyyy-mm-dd"),'Activity Daily Summary'!$A$4:$K$1254,6,FALSE),"")) | F33: =IF(A33="","",IFERROR(VLOOKUP($B$3&"|"&TEXT(A33,"yyyy-mm-dd"),'Activity Daily Summary'!$A$4:$K$1254,7,FALSE)&IF(VLOOKUP($B$3&"|"&TEXT(A33,"yyyy-mm-dd"),'Activity Daily Summary'!$A$4:$K$1254,8,FALSE)="",""," — "&VLOOKUP($B$3&"|"&TEXT(A33,"yyyy-mm-dd"),'Activity Daily Summary'!$A$4:$K$1254,8,FALSE)),"")) | G33: =IF(A33="","",IFERROR(VLOOKUP($B$3&"|"&TEXT(A33,"yyyy-mm-dd"),'Activity Daily Summary'!$A$4:$K$1254,9,FALSE),0)) -> 0 | H33: =IF(A33="","",IFERROR(VLOOKUP($B$3&"|"&TEXT(A33,"yyyy-mm-dd"),'Activity Daily Summary'!$A$4:$K$1254,11,FALSE),"No recorded activity")) -> No recorded activity
A34: =IF(19<=$H$3-$E$3,$E$3+19,"") -> 46101 | B34: =IF(A34="","",TEXT(A34,"ddd")) -> Fri | C34: =IF(A34="","",IFERROR(VLOOKUP($B$3&"|"&TEXT(A34,"yyyy-mm-dd"),'Activity Daily Summary'!$A$4:$K$1254,10,FALSE),"No recorded activity")) -> No recorded activity | D34: =IF(A34="","",IFERROR(VLOOKUP($B$3&"|"&TEXT(A34,"yyyy-mm-dd"),'Activity Daily Summary'!$A$4:$K$1254,5,FALSE),"")) | E34: =IF(A34="","",IFERROR(VLOOKUP($B$3&"|"&TEXT(A34,"yyyy-mm-dd"),'Activity Daily Summary'!$A$4:$K$1254,6,FALSE),"")) | F34: =IF(A34="","",IFERROR(VLOOKUP($B$3&"|"&TEXT(A34,"yyyy-mm-dd"),'Activity Daily Summary'!$A$4:$K$1254,7,FALSE)&IF(VLOOKUP($B$3&"|"&TEXT(A34,"yyyy-mm-dd"),'Activity Daily Summary'!$A$4:$K$1254,8,FALSE)="",""," — "&VLOOKUP($B$3&"|"&TEXT(A34,"yyyy-mm-dd"),'Activity Daily Summary'!$A$4:$K$1254,8,FALSE)),"")) | G34: =IF(A34="","",IFERROR(VLOOKUP($B$3&"|"&TEXT(A34,"yyyy-mm-dd"),'Activity Daily Summary'!$A$4:$K$1254,9,FALSE),0)) -> 0 | H34: =IF(A34="","",IFERROR(VLOOKUP($B$3&"|"&TEXT(A34,"yyyy-mm-dd"),'Activity Daily Summary'!$A$4:$K$1254,11,FALSE),"No recorded activity")) -> No recorded activity
A35: =IF(20<=$H$3-$E$3,$E$3+20,"") -> 46102 | B35: =IF(A35="","",TEXT(A35,"ddd")) -> Sat | C35: =IF(A35="","",IFERROR(VLOOKUP($B$3&"|"&TEXT(A35,"yyyy-mm-dd"),'Activity Daily Summary'!$A$4:$K$1254,10,FALSE),"No recorded activity")) -> No recorded activity | D35: =IF(A35="","",IFERROR(VLOOKUP($B$3&"|"&TEXT(A35,"yyyy-mm-dd"),'Activity Daily Summary'!$A$4:$K$1254,5,FALSE),"")) | E35: =IF(A35="","",IFERROR(VLOOKUP($B$3&"|"&TEXT(A35,"yyyy-mm-dd"),'Activity Daily Summary'!$A$4:$K$1254,6,FALSE),"")) | F35: =IF(A35="","",IFERROR(VLOOKUP($B$3&"|"&TEXT(A35,"yyyy-mm-dd"),'Activity Daily Summary'!$A$4:$K$1254,7,FALSE)&IF(VLOOKUP($B$3&"|"&TEXT(A35,"yyyy-mm-dd"),'Activity Daily Summary'!$A$4:$K$1254,8,FALSE)="",""," — "&VLOOKUP($B$3&"|"&TEXT(A35,"yyyy-mm-dd"),'Activity Daily Summary'!$A$4:$K$1254,8,FALSE)),"")) | G35: =IF(A35="","",IFERROR(VLOOKUP($B$3&"|"&TEXT(A35,"yyyy-mm-dd"),'Activity Daily Summary'!$A$4:$K$1254,9,FALSE),0)) -> 0 | H35: =IF(A35="","",IFERROR(VLOOKUP($B$3&"|"&TEXT(A35,"yyyy-mm-dd"),'Activity Daily Summary'!$A$4:$K$1254,11,FALSE),"No recorded activity")) -> No recorded activity
A36: =IF(21<=$H$3-$E$3,$E$3+21,"") -> 46103 | B36: =IF(A36="","",TEXT(A36,"ddd")) -> Sun | C36: =IF(A36="","",IFERROR(VLOOKUP($B$3&"|"&TEXT(A36,"yyyy-mm-dd"),'Activity Daily Summary'!$A$4:$K$1254,10,FALSE),"No recorded activity")) -> No recorded activity | D36: =IF(A36="","",IFERROR(VLOOKUP($B$3&"|"&TEXT(A36,"yyyy-mm-dd"),'Activity Daily Summary'!$A$4:$K$1254,5,FALSE),"")) | E36: =IF(A36="","",IFERROR(VLOOKUP($B$3&"|"&TEXT(A36,"yyyy-mm-dd"),'Activity Daily Summary'!$A$4:$K$1254,6,FALSE),"")) | F36: =IF(A36="","",IFERROR(VLOOKUP($B$3&"|"&TEXT(A36,"yyyy-mm-dd"),'Activity Daily Summary'!$A$4:$K$1254,7,FALSE)&IF(VLOOKUP($B$3&"|"&TEXT(A36,"yyyy-mm-dd"),'Activity Daily Summary'!$A$4:$K$1254,8,FALSE)="",""," — "&VLOOKUP($B$3&"|"&TEXT(A36,"yyyy-mm-dd"),'Activity Daily Summary'!$A$4:$K$1254,8,FALSE)),"")) | G36: =IF(A36="","",IFERROR(VLOOKUP($B$3&"|"&TEXT(A36,"yyyy-mm-dd"),'Activity Daily Summary'!$A$4:$K$1254,9,FALSE),0)) -> 0 | H36: =IF(A36="","",IFERROR(VLOOKUP($B$3&"|"&TEXT(A36,"yyyy-mm-dd"),'Activity Daily Summary'!$A$4:$K$1254,11,FALSE),"No recorded activity")) -> No recorded activity
A37: =IF(22<=$H$3-$E$3,$E$3+22,"") -> 46104 | B37: =IF(A37="","",TEXT(A37,"ddd")) -> Mon | C37: =IF(A37="","",IFERROR(VLOOKUP($B$3&"|"&TEXT(A37,"yyyy-mm-dd"),'Activity Daily Summary'!$A$4:$K$1254,10,FALSE),"No recorded activity")) -> No recorded activity | D37: =IF(A37="","",IFERROR(VLOOKUP($B$3&"|"&TEXT(A37,"yyyy-mm-dd"),'Activity Daily Summary'!$A$4:$K$1254,5,FALSE),"")) | E37: =IF(A37="","",IFERROR(VLOOKUP($B$3&"|"&TEXT(A37,"yyyy-mm-dd"),'Activity Daily Summary'!$A$4:$K$1254,6,FALSE),"")) | F37: =IF(A37="","",IFERROR(VLOOKUP($B$3&"|"&TEXT(A37,"yyyy-mm-dd"),'Activity Daily Summary'!$A$4:$K$1254,7,FALSE)&IF(VLOOKUP($B$3&"|"&TEXT(A37,"yyyy-mm-dd"),'Activity Daily Summary'!$A$4:$K$1254,8,FALSE)="",""," — "&VLOOKUP($B$3&"|"&TEXT(A37,"yyyy-mm-dd"),'Activity Daily Summary'!$A$4:$K$1254,8,FALSE)),"")) | G37: =IF(A37="","",IFERROR(VLOOKUP($B$3&"|"&TEXT(A37,"yyyy-mm-dd"),'Activity Daily Summary'!$A$4:$K$1254,9,FALSE),0)) -> 0 | H37: =IF(A37="","",IFERROR(VLOOKUP($B$3&"|"&TEXT(A37,"yyyy-mm-dd"),'Activity Daily Summary'!$A$4:$K$1254,11,FALSE),"No recorded activity")) -> No recorded activity
A38: =IF(23<=$H$3-$E$3,$E$3+23,"") -> 46105 | B38: =IF(A38="","",TEXT(A38,"ddd")) -> Tue | C38: =IF(A38="","",IFERROR(VLOOKUP($B$3&"|"&TEXT(A38,"yyyy-mm-dd"),'Activity Daily Summary'!$A$4:$K$1254,10,FALSE),"No recorded activity")) -> No recorded activity | D38: =IF(A38="","",IFERROR(VLOOKUP($B$3&"|"&TEXT(A38,"yyyy-mm-dd"),'Activity Daily Summary'!$A$4:$K$1254,5,FALSE),"")) | E38: =IF(A38="","",IFERROR(VLOOKUP($B$3&"|"&TEXT(A38,"yyyy-mm-dd"),'Activity Daily Summary'!$A$4:$K$1254,6,FALSE),"")) | F38: =IF(A38="","",IFERROR(VLOOKUP($B$3&"|"&TEXT(A38,"yyyy-mm-dd"),'Activity Daily Summary'!$A$4:$K$1254,7,FALSE)&IF(VLOOKUP($B$3&"|"&TEXT(A38,"yyyy-mm-dd"),'Activity Daily Summary'!$A$4:$K$1254,8,FALSE)="",""," — "&VLOOKUP($B$3&"|"&TEXT(A38,"yyyy-mm-dd"),'Activity Daily Summary'!$A$4:$K$1254,8,FALSE)),"")) | G38: =IF(A38="","",IFERROR(VLOOKUP($B$3&"|"&TEXT(A38,"yyyy-mm-dd"),'Activity Daily Summary'!$A$4:$K$1254,9,FALSE),0)) -> 0 | H38: =IF(A38="","",IFERROR(VLOOKUP($B$3&"|"&TEXT(A38,"yyyy-mm-dd"),'Activity Daily Summary'!$A$4:$K$1254,11,FALSE),"No recorded activity")) -> No recorded activity
A39: =IF(24<=$H$3-$E$3,$E$3+24,"") -> 46106 | B39: =IF(A39="","",TEXT(A39,"ddd")) -> Wed | C39: =IF(A39="","",IFERROR(VLOOKUP($B$3&"|"&TEXT(A39,"yyyy-mm-dd"),'Activity Daily Summary'!$A$4:$K$1254,10,FALSE),"No recorded activity")) -> No recorded activity | D39: =IF(A39="","",IFERROR(VLOOKUP($B$3&"|"&TEXT(A39,"yyyy-mm-dd"),'Activity Daily Summary'!$A$4:$K$1254,5,FALSE),"")) | E39: =IF(A39="","",IFERROR(VLOOKUP($B$3&"|"&TEXT(A39,"yyyy-mm-dd"),'Activity Daily Summary'!$A$4:$K$1254,6,FALSE),"")) | F39: =IF(A39="","",IFERROR(VLOOKUP($B$3&"|"&TEXT(A39,"yyyy-mm-dd"),'Activity Daily Summary'!$A$4:$K$1254,7,FALSE)&IF(VLOOKUP($B$3&"|"&TEXT(A39,"yyyy-mm-dd"),'Activity Daily Summary'!$A$4:$K$1254,8,FALSE)="",""," — "&VLOOKUP($B$3&"|"&TEXT(A39,"yyyy-mm-dd"),'Activity Daily Summary'!$A$4:$K$1254,8,FALSE)),"")) | G39: =IF(A39="","",IFERROR(VLOOKUP($B$3&"|"&TEXT(A39,"yyyy-mm-dd"),'Activity Daily Summary'!$A$4:$K$1254,9,FALSE),0)) -> 0 | H39: =IF(A39="","",IFERROR(VLOOKUP($B$3&"|"&TEXT(A39,"yyyy-mm-dd"),'Activity Daily Summary'!$A$4:$K$1254,11,FALSE),"No recorded activity")) -> No recorded activity
A40: =IF(25<=$H$3-$E$3,$E$3+25,"") -> 46107 | B40: =IF(A40="","",TEXT(A40,"ddd")) -> Thu | C40: =IF(A40="","",IFERROR(VLOOKUP($B$3&"|"&TEXT(A40,"yyyy-mm-dd"),'Activity Daily Summary'!$A$4:$K$1254,10,FALSE),"No recorded activity")) -> No recorded activity | D40: =IF(A40="","",IFERROR(VLOOKUP($B$3&"|"&TEXT(A40,"yyyy-mm-dd"),'Activity Daily Summary'!$A$4:$K$1254,5,FALSE),"")) | E40: =IF(A40="","",IFERROR(VLOOKUP($B$3&"|"&TEXT(A40,"yyyy-mm-dd"),'Activity Daily Summary'!$A$4:$K$1254,6,FALSE),"")) | F40: =IF(A40="","",IFERROR(VLOOKUP($B$3&"|"&TEXT(A40,"yyyy-mm-dd"),'Activity Daily Summary'!$A$4:$K$1254,7,FALSE)&IF(VLOOKUP($B$3&"|"&TEXT(A40,"yyyy-mm-dd"),'Activity Daily Summary'!$A$4:$K$1254,8,FALSE)="",""," — "&VLOOKUP($B$3&"|"&TEXT(A40,"yyyy-mm-dd"),'Activity Daily Summary'!$A$4:$K$1254,8,FALSE)),"")) | G40: =IF(A40="","",IFERROR(VLOOKUP($B$3&"|"&TEXT(A40,"yyyy-mm-dd"),'Activity Daily Summary'!$A$4:$K$1254,9,FALSE),0)) -> 0 | H40: =IF(A40="","",IFERROR(VLOOKUP($B$3&"|"&TEXT(A40,"yyyy-mm-dd"),'Activity Daily Summary'!$A$4:$K$1254,11,FALSE),"No recorded activity")) -> No recorded activity
